data/sample_orders.csv
symbol,action,id,side,type,price,qty
AAPL,A,1,S,L,189.55,100
AAPL,A,2,S,L,189.60,200
AAPL,A,3,B,L,189.45,150
AAPL,A,4,B,L,189.45,50
MSFT,A,5,S,L,412.30,80
MSFT,A,6,B,L,412.10,120
AAPL,A,7,B,L,189.60,250
AAPL,A,8,S,M,,120
MSFT,A,9,B,I,412.30,200
MSFT,A,10,S,F,412.00,500
MSFT,A,11,S,F,412.10,100
AAPL,M,4,,,189.40,50
AAPL,C,2,,,,
AAPL,A,12,S,L,189.50,40
MSFT,A,13,S,L,412.25,60
